Workbook

Sheet JIRA DATA
A1: INSTRUCTIONS: Paste your JIRA export here (replace rows 3 onward, keep headers in row 2)
A2: Issue Type | B2: Issue key | C2: Issue id | D2: Summary | E2: Status | F2: Epic Link | G2: Story Points | H2: Labels | I2: Sprint | J2: PI
A3: Story | B3: SSF-164 | D3: [MOB] Routing from the menu to the selected element screen | E3: Canceled | F3: App Menu | G3: 3 | H3: Mobile, SSF_MOBILE_APP | I3: SSF - PI 01
A4: Story | B4: SSF-163 | D4: {READY} [MOB] Display the menu | E4: Open | F4: App Menu | G4: 2 | H4: Mobile, SSF_MOBILE_APP, SSF_PI#02 | I4: SSF - PI 02 | J4: SSF_PI#02
A5: Story | B5: SSF-182 | D5: {DEV READY} [BACK] Endpoint to retrieve vessels data from FMC | E5: Open | F5: Data Exchange w/FMC | G5: 3 | H5: SSF_MOBILE_APP | I5: PI 01 - EXTRA
A6: Story | B6: SSF-196 | D6: [MOB] Catches preference | E6: Open | F6: Departure Declaration | G6: 3 | H6: Mobile, SSF_MOBILE_APP, SSF_PI#02 | I6: SSF - PI 02 | J6: SSF_PI#02
A7: Story | B7: SSF-195 | D7: [MOB] Declare Catches onboard | E7: Open | F7: Departure Declaration | G7: 5 | H7: Mobile, SSF_MOBILE_APP, SSF_PI#02 | I7: SSF - PI 02 | J7: SSF_PI#02
A8: Story | B8: SSF-194 | D8: [MOB] Submit Departure Declaration | E8: Open | F8: Departure Declaration | G8: 2 | H8: Mobile, SSF_MOBILE_APP, SSF_PI#02 | I8: SSF - PI 02 | J8: SSF_PI#02
A9: Story | B9: SSF-193 | D9: [MOB] Departure Declaration Recap Screen | E9: Open | F9: Departure Declaration | G9: 3 | H9: Mobile, SSF_MOBILE_APP, SSF_PI#02 | I9: SSF - PI 02 | J9: SSF_PI#02
A10: Story | B10: SSF-192 | D10: [BACK] Submit Departure Declaration | E10: Open | F10: Departure Declaration | G10: 3 | H10: Backend, SSF_MOBILE_APP, SSF_PI#02 | I10: SSF - PI 02 | J10: SSF_PI#02
A11: Story | B11: SSF-191 | D11: [MOB] Gears onboard | E11: Open | F11: Departure Declaration | G11: 5 | H11: Mobile, SSF_MOBILE_APP, SSF_PI#02 | I11: SSF - PI 02 | J11: SSF_PI#02
A12: Story | B12: SSF-190 | D12: [BACK] Data import endpoint | E12: Open | F12: Departure Declaration | G12: 5 | H12: Backend, SSF_MOBILE_APP, SSF_PI#02 | I12: SSF - PI 02 | J12: SSF_PI#02
A13: Story | B13: SSF-189 | D13: [MOB] Departure Port selection | E13: Open | F13: Departure Declaration | G13: 5 | H13: Mobile, SSF_MOBILE_APP, SSF_PI#02 | I13: SSF - PI 02 | J13: SSF_PI#02
A14: Story | B14: SSF-140 | D14: [MOB] Vessel's Empty Gear Management Screen | E14: Ready | F14: Gear Management | G14: 2 | H14: Mobile, SSF_MOBILE_APP, SSF_PI#02 | I14: SSF - PI 01 | J14: SSF_PI#02
A15: Story | B15: SSF-188 | D15: [MOB] Error Management / Messages | E15: Open | F15: Gear Management | G15: 2 | H15: SSF_MOBILE_APP, SSF_PI#02, mobile | I15: SSF - PI 02 | J15: SSF_PI#02
A16: Story | B16: SSF-152 | D16: [BACK] Error Management / Security | E16: Open | F16: Gear Management | G16: 2 | H16: Backend, SSF_MOBILE_APP, SSF_PI#02 | I16: SSF - PI 02 | J16: SSF_PI#02
A17: Story | B17: SSF-151 | D17: [BACK] Delete Gear | E17: Open | F17: Gear Management | G17: 3 | H17: Backend, SSF_MOBILE_APP, SSF_PI#02 | I17: SSF - PI 02 | J17: SSF_PI#02
... A38: Story | B38: SSF-205 | D38: [MOB] Hauls screen | E38: Open | F38: Hauls | G38: 3 | H38: Mobile, SSF_MOBILE_APP, SSF_PI#02 | I38: SSF - PI 02 | J38: SSF_PI#02
A39: Story | B39: SSF-160 | D39: [MOB] Fishing Trips Widget | E39: Open | F39: Home Screen | G39: 1 | H39: Mobile, SSF_MOBILE_APP | I39: PI 01 - EXTRA
A40: Story | B40: SSF-155 | D40: {READY} [MOB] Vessel selection quick access | E40: Ready | F40: Home Screen | G40: 2 | H40: Mobile, SSF_MOBILE_APP | I40: PI 01 - EXTRA
A41: Story | B41: SSF-184 | D41: TO UPDATE - [MOB] Session & Network Widget - Reconnection Logic | E41: Ready | F41: Home Screen | G41: 2 | H41: Mobile, SSF_MOBILE_APP, SSF_PI#01 | I41: SSF - PI 01 | J41: SSF_PI#01
A42: Story | B42: SSF-173 | D42: [MOB] Home Screen (Mocked) | E42: Ready | F42: Home Screen | G42: 2 | H42: Mobile, SSF_MOBILE_APP, SSF_PI#01 | I42: SSF - PI 01 | J42: SSF_PI#01
A43: Story | B43: SSF-153 | D43: TO UPDATE - [MOB] Session & Network Widget | E43: Ready | F43: Home Screen | G43: 3 | H43: Mobile, SSF_MOBILE_APP, SSF_PI#01 | I43: SSF - PI 01 | J43: SSF_PI#01
A44: Story | B44: SSF-175 | D44: {DEV READY} [MOB] Setup AWS for Login redirect URI (App link, Universal Link) | E44: Ready | F44: INFRA | G44: 2 | H44: SSF_MOBILE_APP, SSF_PI#01 | I44: SSF - 01 | J44: SSF_PI#01
A45: Story | B45: SSF-104 | D45: {DEV READY} [BACK] Gitlab CI for Ansible | E45: Open | F45: INFRA | G45: 2 | H45: SSF_MOBILE_APP, SSF_PI#01, backend | I45: SSF - PI 01 | J45: SSF_PI#01
A46: Story | B46: SSF-103 | D46: {DEV READY} [BACK] Deploy App Server on AWS (Ansible) | E46: Open | F46: INFRA | G46: 2 | H46: SSF_MOBILE_APP, SSF_PI#01, backend | I46: SSF - PI 01 | J46: SSF_PI#01
A47: Story | B47: SSF-100 | D47: {DEV READY} [BACK] Infra as Code implementation on AWS (Terraform) | E47: In review | F47: INFRA | G47: 5 | H47: SSF_MOBILE_APP, SSF_PI#01, backend | I47: SSF - PI 01 | J47: SSF_PI#01
A48: Story | B48: SSF-99 | D48: {DEV READY} [BACK] Initiate CI/CD | E48: Open | F48: INFRA | G48: 2 | H48: SSF_MOBILE_APP, SSF_PI#01 | I48: SSF - PI 01 | J48: SSF_PI#01
A49: Story | B49: SSF-98 | D49: {DEV READY} [MOB] Initiate CI/CD | E49: Open | F49: INFRA | G49: 2 | H49: SSF_MOBILE_APP, SSF_PI#01 | I49: SSF - PI 01 | J49: SSF_PI#01
A50: Story | B50: SSF-169 | D50: [BACK] Languages MDR Ref Data | E50: Open | F50: Language Management | G50: 5 | H50: Backend, SSF_MOBILE_APP | I50: PI 01 - EXTRA
A51: Story | B51: SSF-168 | D51: [MOB] Language Override | E51: Open | F51: Language Management | G51: 5 | H51: SSF_MOBILE_APP, mobile | I51: PI 01 - EXTRA
A52: Story | B52: SSF-167 | D52: [MOB] Initialization of internationalization | E52: Done | F52: Language Management | G52: 3 | H52: Mobile, SSF_MOBILE_APP, SSF_PI#01 | I52: SSF - 01 | J52: SSF_PI#01
A53: Story | B53: SSF-185 | D53: [MOB] Handle Multiple devices login | E53: Open | F53: Login | G53: 2 | H53: Mobile, SSF_MOBILE_APP | I53: PI 01 - EXTRA
A54: Story | B54: SSF-181 | D54: {NEEDS DISCUSSION} [MOB] Retrieve user data from Identity Provider | E54: Open | F54: Login | G54: 3 | H54: SSF_MOBILE_APP | I54: PI 01 - EXTRA
A55: Story | B55: SSF-178 | D55: [MOB] Logout | E55: Open | F55: Login | G55: 5 | H55: Mobile, SSF_MOBILE_APP | I55: PI 01 - EXTRA
A56: Story | B56: SSF-177 | D56: [MOB] Handle multi accounts login (case of ongoing tracking session) | E56: Open | F56: Login | G56: 5 | H56: Mobile, SSF_MOBILE_APP | I56: PI 01 - EXTRA
A57: Story | B57: SSF-203 | D57: [MOB] Implement Refresh Session | E57: Open | F57: Login | G57: 2 | H57: Mobile, SSF_MOBILE_APP, SSF_PI#01 | I57: SSF - 01 | J57: SSF_PI#01
A58: Story | B58: SSF-202 | D58: [MOB] Vessel selection screen Errors Management | E58: Open | F58: Login | G58: 3 | H58: Mobile, SSF_MOBILE_APP, SSF_PI#01 | I58: SSF - 01 | J58: SSF_PI#01
A59: Story | B59: SSF-120 | D59: [BACK] Endpoint GET vessels for the user | E59: Ready | F59: Login | G59: 5 | H59: SSF_MOBILE_APP, SSF_PI#01, backend | I59: SSF - 01 | J59: SSF_PI#01
A60: Story | B60: SSF-118 | D60: [MOB] Vessel selection screen (Mocked) | E60: Done | F60: Login | G60: 3 | H60: Mobile, SSF_MOBILE_APP, SSF_PI#01 | I60: SSF - 01 | J60: SSF_PI#01
...

Sheet DASHBOARD
A1: REFINEMENT TRACKER - DASHBOARD
A2: Last Updated | B2: =TODAY() | C2: Current Sprint | D2: 1
A4: QUICK METRICS
A6: Total Stories Whole Backlog | C6: =COUNTA('JIRA DATA'!A:A)-2 | F6: Status | G6: =IF(G9="","-",IF(G9>=6.5,"🟢 On Track",IF(G9>=4,"🟡 At Risk","🔴 Critical")))
A7: To Refine (Open) | C7: =COUNTIF('JIRA DATA'!E:E,"Open") | F7: Risk Level | G7: =IF(C10>60,"🔴 HIGH",IF(C10>40,"🟡 MEDIUM","🟢 LOW"))
A8: Already Refined (Ready) | C8: =COUNTIF('JIRA DATA'!E:E,"Ready")
A9: Completed So Far | C9: =SUM('SESSION LOG'!F:F) | F9: Current Velocity | G9: =IF(COUNTA('SESSION LOG'!F2:F16)=0,0,AVERAGE('SESSION LOG'!F2:F16))
A10: Remaining | C10: =IF(ISBLANK(C9),C7,C7-C9) | F10: Target Velocity | G10: 6.5
A11: Progress % | C11: =IF(C9=0,0,C9/C7) | F11: Projected Completion | G11: =IF(OR(G9=0,G9=""),"TBD","Sprint "&ROUNDUP(C10/G9/3+1,0))
A13: SESSION SUMMARY (LAST 3)
B14: Session | C14: Sprint | D14: Date | F14: Stories Refined | G14: Cumulative | H14: Status
B15: {=IF(COUNTA('SESSION LOG'!A:A)<=1,"",INDEX('SESSION LOG'!A:A,COUNTA('SESSION LOG'!A:A)))} | C15: {=IF(COUNTA('SESSION LOG'!A:A)<=1,"",INDEX('SESSION LOG'!B:B,COUNTA('SESSION LOG'!A:A)))} | D15: {=IF(COUNTA('SESSION LOG'!A:A)<=1,"",INDEX('SESSION LOG'!C:C,COUNTA('SESSION LOG'!A:A)))} | F15: {=IF(COUNTA('SESSION LOG'!A:A)<=1,"",INDEX('SESSION LOG'!F:F,COUNTA('SESSION LOG'!A:A)))} | G15: {=IF(COUNTA('SESSION LOG'!A:A)<=1,"",INDEX('SESSION LOG'!G:G,COUNTA('SESSION LOG'!A:A)))} | H15: {=IF(COUNTA('SESSION LOG'!A:A)<=1,"",INDEX('SESSION LOG'!J:J,COUNTA('SESSION LOG'!A:A)))}
B16: {=IF(COUNTA('SESSION LOG'!A:A)<=2,"",INDEX('SESSION LOG'!A:A,COUNTA('SESSION LOG'!A:A)-1))} | C16: {=IF(COUNTA('SESSION LOG'!A:A)<=2,"",INDEX('SESSION LOG'!B:B,COUNTA('SESSION LOG'!A:A)-1))} | D16: {=IF(COUNTA('SESSION LOG'!A:A)<=2,"",INDEX('SESSION LOG'!C:C,COUNTA('SESSION LOG'!A:A)-1))} | F16: {=IF(COUNTA('SESSION LOG'!A:A)<=2,"",INDEX('SESSION LOG'!F:F,COUNTA('SESSION LOG'!A:A)-1))} | G16: {=IF(COUNTA('SESSION LOG'!A:A)<=2,"",INDEX('SESSION LOG'!G:G,COUNTA('SESSION LOG'!A:A)-1))} | H16: {=IF(COUNTA('SESSION LOG'!A:A)<=2,"",INDEX('SESSION LOG'!J:J,COUNTA('SESSION LOG'!A:A)-1))}
B17: {=IF(COUNTA('SESSION LOG'!A:A)<=3,"",INDEX('SESSION LOG'!A:A,COUNTA('SESSION LOG'!A:A)-2))} | C17: {=IF(COUNTA('SESSION LOG'!A:A)<=3,"",INDEX('SESSION LOG'!B:B,COUNTA('SESSION LOG'!A:A)-2))} | D17: {=IF(COUNTA('SESSION LOG'!A:A)<=3,"",INDEX('SESSION LOG'!C:C,COUNTA('SESSION LOG'!A:A)-2))} | F17: {=IF(COUNTA('SESSION LOG'!A:A)<=3,"",INDEX('SESSION LOG'!F:F,COUNTA('SESSION LOG'!A:A)-2))} | G17: {=IF(COUNTA('SESSION LOG'!A:A)<=3,"",INDEX('SESSION LOG'!G:G,COUNTA('SESSION LOG'!A:A)-2))} | H17: {=IF(COUNTA('SESSION LOG'!A:A)<=3,"",INDEX('SESSION LOG'!J:J,COUNTA('SESSION LOG'!A:A)-2))}
A19: WEEKLY REPORT (Auto-Generated)
A20: Report Text | B20: ="REFINEMENT PROGRESS - Week of "&TEXT(TODAY(),"MMM DD, YYYY")&CHAR(10)&CHAR(10)&"✅ STORIES REFINED THIS WEEK"&CHAR(10)&" • Sessions conducted: "&COUNTIFS('SESSION LOG'!C:C,">="&TODAY()-7,'SESSION LOG'!C:C,"<="&TODAY())&CHAR(10)&" • Stories moved to Ready: "&SUMIFS('SESSION LOG'!F:F,'SESSION LOG'!C:C,">="&TODAY()-7,'SESSION LOG'!C:C,"<="&TODAY())&CHAR(10)&" • Cumulative progress: "&C9&"/"&C7&" ("&ROUND(C11,0)&"%)"&CHAR(10)&CHAR(10)&"📈 VELOCITY METRICS"&CHAR(10)&" • Current velocity: "&ROUND(G9,1)&" stories/session"&CHAR(10)&" • Target velocity: 6.5 stories/session"&CHAR(10)&" • Status: "&G6&CHAR(10)&CHAR(10)&"📅 TIMELINE"&CHAR(10)&" • Sessions remaining: "&(15-COUNTA('SESSION LOG'!F2:F16))&CHAR(10)&" • Projected completion: "&G11&CHAR(10)&" • On track for Sprint 5: "&IF(G11="Sprint 5","YES ✅",IF(G11="Sprint 6","ALMOST ⚠️","NO ❌"))
A27: 📊 PI PROGRESS
A28: See PI PROGRESS sheet for detailed PI tracking →
A30: 📊 PI PROGRESS
A31: See PI PROGRESS sheet for PI tracking →

Sheet PI PROGRESS
A1: PI PROGRESS TRACKER
A2: PI Label | B2: Total Stories | C2: Refined (Ready) | D2: To Refine (Open) | E2: Other Status | F2: % Complete | G2: Progress | H2: Status
A3: SSF_PI#01 | B3: =COUNTIF('JIRA DATA'!J:J,A3) | C3: =COUNTIFS('JIRA DATA'!J:J,A3,'JIRA DATA'!E:E,"Ready") | D3: =COUNTIFS('JIRA DATA'!J:J,A3,'JIRA DATA'!E:E,"Open") | E3: =B3-C3-D3 | F3: =IF(B3=0,0,C3/B3) | G3: =C3&"/"&B3 | H3: =IF(F3>0.7,"🟢",IF(F3>0.3,"🟡","🔴"))
A4: SSF_PI#02 | B4: =COUNTIF('JIRA DATA'!J:J,A4) | C4: =COUNTIFS('JIRA DATA'!J:J,A4,'JIRA DATA'!E:E,"Ready") | D4: =COUNTIFS('JIRA DATA'!J:J,A4,'JIRA DATA'!E:E,"Open") | E4: =B4-C4-D4 | F4: =IF(B4=0,0,C4/B4) | G4: =C4&"/"&B4 | H4: =IF(F4>0.7,"🟢",IF(F4>0.3,"🟡","🔴"))

Sheet SESSION CALENDAR
A1: SESSION CALENDAR - All 13 Remaining Sessions
A2: Session # | B2: Sprint | C2: Week | D2: Date | F2: Time | G2: Duration | H2: Target | I2: Prep Deadline | J2: Status | K2: Notes
A3: 3 | B3: 1 | C3: 2 | D3: 45973 | F3: 0.41666667 | G3: 60 | H3: 7 | J3: 🟡 This Week
A4: 4 | B4: 2 | C4: 1 | D4: 45980 | G4: 60 | H4: 7 | J4: 🟢 Upcoming
A5: 5 | B5: 2 | C5: 1 | D5: 45982 | G5: 60 | H5: 7 | J5: 🟢 Upcoming
A6: 6 | B6: 2 | C6: 2 | D6: 45987 | G6: 60 | H6: 7 | J6: 🟢 Upcoming
A7: 7 | B7: 3 | C7: 1 | D7: 45994 | G7: 60 | H7: 7 | J7: 🟢 Upcoming
A8: 8 | B8: 3 | C8: 1 | D8: 45996 | G8: 60 | H8: 7 | J8: 🟢 Upcoming
A9: 9 | B9: 3 | C9: 2 | D9: 46001 | G9: 60 | H9: 7 | J9: 🟢 Upcoming
A10: 10 | B10: 4 | C10: 1 | D10: 46008 | G10: 60 | H10: 7 | J10: 🟢 Upcoming
A11: 11 | B11: 4 | C11: 1 | D11: 46010 | G11: 60 | H11: 7 | J11: 🟢 Upcoming
A12: 12 | B12: 4 | C12: 2 | D12: 46015 | G12: 60 | H12: 7 | J12: 🟢 Upcoming
A13: 13 | B13: 5 | C13: 1 | D13: 46029 | G13: 60 | H13: 7 | J13: 🟢 Upcoming
A14: 14 | B14: 5 | C14: 1 | D14: 46031 | G14: 60 | H14: 7 | J14: 🟢 Upcoming
A15: 15 | B15: 5 | C15: 2 | D15: 46036 | G15: 60 | H15: 7 | J15: 🟢 Upcoming

Sheet SESSIONS AGENDA
B1: Refinement session #03 - 12/11/2025
B2: Date | C2: 45973
B3: Time | C3: 0.41666667
B4: Topics | C4: Gear Management
B5: Goal | C5: All items must be "Ready" by the end of Sprint #02
B6: Sprint | C6: 2
B7: Agenda for Refinement session #03
B8: Story Number | C8: Summary | D8: Status
B9: SSF-141 | C9: [MOB] Register new gear - Init Creation Form | D9: Ready
B11: SSF-144 | C11: [MOB] Vessel's Gear Screen - Gear List | D11: Ready
B15: Gear Characteristics Workshop - 13/11/2025
B16: Date
B17: Sprint | C17: 2
B18: Agenda for the Workshop
B22: Refinement session #04
B23: Date | C23: 45973
B24: Time | C24: 0.41666667
B25: Topics | C25: Gear Management
B26: Goal | C26: All items must be "Ready" by the end of Sprint #02
B27: Sprint | C27: 2
B28: Agenda for Refinement session #04
B29: Story Number | C29: Summary | D29: Status
B30: SSF-143 | C30: [MOB] Register new gear - Gear characteristics | D30: Open
B31: SSF-147 | C31: [BACK] Register new gear | D31: Open
B32: SSF-142 | C32: [MOB] Register new gear - Form submission | D32: Open
B35: SSF-148 | C35: [BACK] List of vessel's gear - New Gear | D35: Open
B36: SSF-149 | C36: [BACK] List of vessel's gear - Retrieval | D36: Open
B37: SSF-145 | C37: [MOB] Edit Gear | D37: Open
B38: SSF-150 | C38: [BACK] Edit Gear | D38: Open
B39: SSF-188 | C39: [MOB] Error Management / Messages | D39: Open
B40: SSF-152 | C40: [BACK] Error Management / Security | D40: Open
B41: SSF-146 | C41: [MOB] Delete Gear | D41: Open
B42: SSF-151 | C42: [BACK] Delete Gear | D42: Open
B44: Refinement session #05
B45: Date
B46: Time
B47: Topics | C47: Departure Declaration
B48: Goal | C48: All items must be "Ready" by the end of Sprint #03
B49: Sprint | C49: 3
B50: Agenda for Refinement session #05
...

Sheet SESSION LOG
A1: SESSION LOG - Data Entry (Update After Each Session)
A2: Session # | B2: Sprint | C2: Date | E2: Target Stories | F2: Stories Refined (ENTER THIS) | G2: Cumulative | H2: Remaining | I2: Velocity | J2: Status | K2: PI(s) Worked
A3: 1 | B3: 1 | C3: 45966 | E3: 7 | F3: 0 | G3: =SUM($F$3:F3) | H3: =DASHBOARD!$C$7-G3 | I3: =F3 | J3: =IF(ISBLANK(I3),"",IF(I3>=6.5,"🟢",IF(I3>=4,"🟡","🔴"))) | K3: Enter PI labels: SSF_PI#01, SSF_PI#02, etc.
A4: 2 | B4: 1 | C4: 45968 | E4: 7 | F4: 1 | G4: =SUM($F$3:F4) | H4: =DASHBOARD!$C$7-G4 | I4: =F4 | J4: =IF(ISBLANK(I4),"",IF(I4>=6.5,"🟢",IF(I4>=4,"🟡","🔴"))) | K4: Team alignment
A5: 3 | B5: 1 | C5: 45973 | E5: 7 | F5: 2 | G5: =SUM($F$3:F5) | H5: =DASHBOARD!$C$7-G5 | I5: =F5 | J5: =IF(ISBLANK(I5),"",IF(I5>=6.5,"🟢",IF(I5>=4,"🟡","🔴"))) | K5: Gear Management
A6: 4 | B6: 2 | C6: 45980 | E6: 7 | G6: =SUM($F$3:F6) | H6: =DASHBOARD!$C$7-G6 | I6: =F6 | J6: =IF(ISBLANK(I6),"",IF(I6>=6.5,"🟢",IF(I6>=4,"🟡","🔴")))
A7: 5 | B7: 2 | C7: 45982 | E7: 7 | G7: =SUM($F$3:F7) | H7: =DASHBOARD!$C$7-G7 | I7: =F7 | J7: =IF(ISBLANK(I7),"",IF(I7>=6.5,"🟢",IF(I7>=4,"🟡","🔴")))
A8: 6 | B8: 2 | C8: 45987 | E8: 7 | G8: =SUM($F$3:F8) | H8: =DASHBOARD!$C$7-G8 | I8: =F8 | J8: =IF(ISBLANK(I8),"",IF(I8>=6.5,"🟢",IF(I8>=4,"🟡","🔴")))
A9: 7 | B9: 3 | C9: 45994 | E9: 7 | G9: =SUM($F$3:F9) | H9: =DASHBOARD!$C$7-G9 | I9: =F9 | J9: =IF(ISBLANK(I9),"",IF(I9>=6.5,"🟢",IF(I9>=4,"🟡","🔴")))
A10: 8 | B10: 3 | C10: 45996 | E10: 7 | G10: =SUM($F$3:F10) | H10: =DASHBOARD!$C$7-G10 | I10: =F10 | J10: =IF(ISBLANK(I10),"",IF(I10>=6.5,"🟢",IF(I10>=4,"🟡","🔴")))
A11: 9 | B11: 3 | C11: 46001 | E11: 7 | G11: =SUM($F$3:F11) | H11: =DASHBOARD!$C$7-G11 | I11: =F11 | J11: =IF(ISBLANK(I11),"",IF(I11>=6.5,"🟢",IF(I11>=4,"🟡","🔴")))
A12: 10 | B12: 4 | C12: 46008 | E12: 7 | G12: =SUM($F$3:F12) | H12: =DASHBOARD!$C$7-G12 | I12: =F12 | J12: =IF(ISBLANK(I12),"",IF(I12>=6.5,"🟢",IF(I12>=4,"🟡","🔴")))
A13: 11 | B13: 4 | C13: 46010 | E13: 7 | G13: =SUM($F$3:F13) | H13: =DASHBOARD!$C$7-G13 | I13: =F13 | J13: =IF(ISBLANK(I13),"",IF(I13>=6.5,"🟢",IF(I13>=4,"🟡","🔴")))
A14: 12 | B14: 4 | C14: 46015 | E14: 7 | G14: =SUM($F$3:F14) | H14: =DASHBOARD!$C$7-G14 | I14: =F14 | J14: =IF(ISBLANK(I14),"",IF(I14>=6.5,"🟢",IF(I14>=4,"🟡","🔴")))
A15: 13 | B15: 5 | C15: 46029 | E15: 7 | G15: =SUM($F$3:F15) | H15: =DASHBOARD!$C$7-G15 | I15: =F15 | J15: =IF(ISBLANK(I15),"",IF(I15>=6.5,"🟢",IF(I15>=4,"🟡","🔴")))
A16: 14 | B16: 5 | C16: 46031 | E16: 7 | G16: =SUM($F$3:F16) | H16: =DASHBOARD!$C$7-G16 | I16: =F16 | J16: =IF(ISBLANK(I16),"",IF(I16>=6.5,"🟢",IF(I16>=4,"🟡","🔴")))
A17: 15 | B17: 5 | C17: 46036 | E17: 7 | G17: =SUM($F$3:F17) | H17: =DASHBOARD!$C$7-G17 | I17: =F17 | J17: =IF(ISBLANK(I17),"",IF(I17>=6.5,"🟢",IF(I17>=4,"🟡","🔴")))
A19: INSTRUCTIONS: Update ONLY column F after each session. Everything else auto-calculates!

Sheet BURNDOWN CHART DATA
A1: TARGET SESSIONS:
A2: BURNDOWN CHART DATA
A3: Session # | B3: Sprint | C3: IDEAL Stories Remaining | D3: ACTUAL Stories Remaining | E3: Variance | F3: Status
A4: 0 | B4: 1 | C4: =DASHBOARD!$C$7 | D4: =DASHBOARD!$C$7 | E4: 0 | F4: Start
A5: {=INDEX('SESSION LOG'!A:A,3)} | B5: {=INDEX('SESSION LOG'!B:B,3)} | C5: =DASHBOARD!$C$7-(DASHBOARD!$C$7/$B$1)*(1) | D5: {=INDEX('SESSION LOG'!H:H,3)} | E5: =D4-C4 | F5: =IF(E4>=0,"🟢",IF(E4>=-5,"🟡","🔴"))
A6: {=INDEX('SESSION LOG'!A:A,4)} | B6: {=INDEX('SESSION LOG'!B:B,4)} | C6: =DASHBOARD!$C$7-(DASHBOARD!$C$7/$B$1)*(2) | D6: {=INDEX('SESSION LOG'!H:H,4)} | E6: =D5-C5 | F6: =IF(E5>=0,"🟢",IF(E5>=-5,"🟡","🔴"))
A7: {=INDEX('SESSION LOG'!A:A,5)} | B7: {=INDEX('SESSION LOG'!B:B,5)} | C7: =DASHBOARD!$C$7-(DASHBOARD!$C$7/$B$1)*(3) | D7: {=INDEX('SESSION LOG'!H:H,5)} | E7: =D6-C6 | F7: =IF(E6>=0,"🟢",IF(E6>=-5,"🟡","🔴"))
A8: {=INDEX('SESSION LOG'!A:A,6)} | B8: {=INDEX('SESSION LOG'!B:B,6)} | C8: =DASHBOARD!$C$7-(DASHBOARD!$C$7/$B$1)*(4) | D8: {=INDEX('SESSION LOG'!H:H,6)} | E8: =D7-C7 | F8: =IF(E7>=0,"🟢",IF(E7>=-5,"🟡","🔴"))
A9: {=INDEX('SESSION LOG'!A:A,7)} | B9: {=INDEX('SESSION LOG'!B:B,7)} | C9: =DASHBOARD!$C$7-(DASHBOARD!$C$7/$B$1)*(5) | D9: {=INDEX('SESSION LOG'!H:H,7)} | E9: =D8-C8 | F9: =IF(E8>=0,"🟢",IF(E8>=-5,"🟡","🔴"))
A10: {=INDEX('SESSION LOG'!A:A,8)} | B10: {=INDEX('SESSION LOG'!B:B,8)} | C10: =DASHBOARD!$C$7-(DASHBOARD!$C$7/$B$1)*(6) | D10: {=INDEX('SESSION LOG'!H:H,8)} | E10: =D9-C9 | F10: =IF(E9>=0,"🟢",IF(E9>=-5,"🟡","🔴"))
A11: {=INDEX('SESSION LOG'!A:A,9)} | B11: {=INDEX('SESSION LOG'!B:B,9)} | C11: =DASHBOARD!$C$7-(DASHBOARD!$C$7/$B$1)*(7) | D11: {=INDEX('SESSION LOG'!H:H,9)} | E11: =D10-C10 | F11: =IF(E10>=0,"🟢",IF(E10>=-5,"🟡","🔴"))
A12: {=INDEX('SESSION LOG'!A:A,10)} | B12: {=INDEX('SESSION LOG'!B:B,10)} | C12: =DASHBOARD!$C$7-(DASHBOARD!$C$7/$B$1)*(8) | D12: {=INDEX('SESSION LOG'!H:H,10)} | E12: =D11-C11 | F12: =IF(E11>=0,"🟢",IF(E11>=-5,"🟡","🔴"))
A13: {=INDEX('SESSION LOG'!A:A,11)} | B13: {=INDEX('SESSION LOG'!B:B,11)} | C13: =DASHBOARD!$C$7-(DASHBOARD!$C$7/$B$1)*(9) | D13: {=INDEX('SESSION LOG'!H:H,11)} | E13: =D12-C12 | F13: =IF(E12>=0,"🟢",IF(E12>=-5,"🟡","🔴"))
A14: {=INDEX('SESSION LOG'!A:A,12)} | B14: {=INDEX('SESSION LOG'!B:B,12)} | C14: =DASHBOARD!$C$7-(DASHBOARD!$C$7/$B$1)*(10) | D14: {=INDEX('SESSION LOG'!H:H,12)} | E14: =D13-C13 | F14: =IF(E13>=0,"🟢",IF(E13>=-5,"🟡","🔴"))
A15: {=INDEX('SESSION LOG'!A:A,13)} | B15: {=INDEX('SESSION LOG'!B:B,13)} | C15: =DASHBOARD!$C$7-(DASHBOARD!$C$7/$B$1)*(11) | D15: {=INDEX('SESSION LOG'!H:H,13)} | E15: =D14-C14 | F15: =IF(E14>=0,"🟢",IF(E14>=-5,"🟡","🔴"))
A16: {=INDEX('SESSION LOG'!A:A,14)} | B16: {=INDEX('SESSION LOG'!B:B,14)} | C16: =DASHBOARD!$C$7-(DASHBOARD!$C$7/$B$1)*(12) | D16: {=INDEX('SESSION LOG'!H:H,14)} | E16: =D15-C15 | F16: =IF(E15>=0,"🟢",IF(E15>=-5,"🟡","🔴"))
A17: {=INDEX('SESSION LOG'!A:A,15)} | B17: {=INDEX('SESSION LOG'!B:B,15)} | C17: =DASHBOARD!$C$7-(DASHBOARD!$C$7/$B$1)*(13) | D17: {=INDEX('SESSION LOG'!H:H,15)} | E17: =D16-C16 | F17: =IF(E16>=0,"🟢",IF(E16>=-5,"🟡","🔴"))
A18: {=INDEX('SESSION LOG'!A:A,16)} | B18: {=INDEX('SESSION LOG'!B:B,16)} | C18: =DASHBOARD!$C$7-(DASHBOARD!$C$7/$B$1)*(14) | D18: {=INDEX('SESSION LOG'!H:H,16)} | E18: =D17-C17 | F18: =IF(E17>=0,"🟢",IF(E17>=-5,"🟡","🔴"))
A19: {=INDEX('SESSION LOG'!A:A,17)} | B19: {=INDEX('SESSION LOG'!B:B,17)} | C19: =DASHBOARD!$C$7-(DASHBOARD!$C$7/$B$1)*(15) | D19: {=INDEX('SESSION LOG'!H:H,17)} | E19: =D18-C18 | F19: =IF(E18>=0,"🟢",IF(E18>=-5,"🟡","🔴"))

Sheet EPIC PROGRESS
A1: EPIC PROGRESS - Auto-calculated from JIRA DATA
A2: Epic ID | B2: Epic Name | C2: Total | D2: Open | E2: Ready | F2: Other | G2: % Complete | H2: Priority | I2: Sprint | J2: PI Filter | K2: Refined in PI | L2: Total in PI | M2: PI Progress
A3: App Menu | B3: App Menu | C3: =COUNTIF('JIRA DATA'!F:F,A3) | D3: =COUNTIFS('JIRA DATA'!F:F,A3,'JIRA DATA'!E:E,"Open") | E3: =COUNTIFS('JIRA DATA'!F:F,A3,'JIRA DATA'!E:E,"Ready") | F3: =C3-D3-E3 | G3: =IF(C3=0,0,E3/C3) | L3: =IF(K3="","-",COUNTIFS('JIRA DATA'!F:F,A3,'JIRA DATA'!J:J,K3,'JIRA DATA'!E:E,"Ready")) | M3: =IF(K3="","-",COUNTIFS('JIRA DATA'!F:F,A3,'JIRA DATA'!J:J,K3)) | N3: =IF(K3="","-",L3&"/"&M3)
A4: Data Exchange w/FMC | B4: Data Exchange w/FMC | C4: =COUNTIF('JIRA DATA'!F:F,A4) | D4: =COUNTIFS('JIRA DATA'!F:F,A4,'JIRA DATA'!E:E,"Open") | E4: =COUNTIFS('JIRA DATA'!F:F,A4,'JIRA DATA'!E:E,"Ready") | F4: =C4-D4-E4 | G4: =IF(C4=0,0,E4/C4) | M4: =IF(L4="","-",COUNTIFS('JIRA DATA'!F:F,A4,'JIRA DATA'!J:J,L4,'JIRA DATA'!E:E,"Ready")) | N4: =IF(L4="","-",COUNTIFS('JIRA DATA'!F:F,A4,'JIRA DATA'!J:J,L4)) | O4: =IF(L4="","-",M4&"/"&N4)
A5: Departure Declaration | B5: Departure Declaration | C5: =COUNTIF('JIRA DATA'!F:F,A5) | D5: =COUNTIFS('JIRA DATA'!F:F,A5,'JIRA DATA'!E:E,"Open") | E5: =COUNTIFS('JIRA DATA'!F:F,A5,'JIRA DATA'!E:E,"Ready") | F5: =C5-D5-E5 | G5: =IF(C5=0,0,E5/C5) | N5: =IF(M5="","-",COUNTIFS('JIRA DATA'!F:F,A5,'JIRA DATA'!J:J,M5,'JIRA DATA'!E:E,"Ready")) | O5: =IF(M5="","-",COUNTIFS('JIRA DATA'!F:F,A5,'JIRA DATA'!J:J,M5)) | P5: =IF(M5="","-",N5&"/"&O5)
A6: Gear Management | B6: Gear Management | C6: =COUNTIF('JIRA DATA'!F:F,A6) | D6: =COUNTIFS('JIRA DATA'!F:F,A6,'JIRA DATA'!E:E,"Open") | E6: =COUNTIFS('JIRA DATA'!F:F,A6,'JIRA DATA'!E:E,"Ready") | F6: =C6-D6-E6 | G6: =IF(C6=0,0,E6/C6) | O6: =IF(N6="","-",COUNTIFS('JIRA DATA'!F:F,A6,'JIRA DATA'!J:J,N6,'JIRA DATA'!E:E,"Ready")) | P6: =IF(N6="","-",COUNTIFS('JIRA DATA'!F:F,A6,'JIRA DATA'!J:J,N6)) | Q6: =IF(N6="","-",O6&"/"&P6)
A7: Hauls | B7: Hauls | C7: =COUNTIF('JIRA DATA'!F:F,A7) | D7: =COUNTIFS('JIRA DATA'!F:F,A7,'JIRA DATA'!E:E,"Open") | E7: =COUNTIFS('JIRA DATA'!F:F,A7,'JIRA DATA'!E:E,"Ready") | F7: =C7-D7-E7 | G7: =IF(C7=0,0,E7/C7) | P7: =IF(O7="","-",COUNTIFS('JIRA DATA'!F:F,A7,'JIRA DATA'!J:J,O7,'JIRA DATA'!E:E,"Ready")) | Q7: =IF(O7="","-",COUNTIFS('JIRA DATA'!F:F,A7,'JIRA DATA'!J:J,O7)) | R7: =IF(O7="","-",P7&"/"&Q7)
A8: Home Screen | B8: Home Screen | C8: =COUNTIF('JIRA DATA'!F:F,A8) | D8: =COUNTIFS('JIRA DATA'!F:F,A8,'JIRA DATA'!E:E,"Open") | E8: =COUNTIFS('JIRA DATA'!F:F,A8,'JIRA DATA'!E:E,"Ready") | F8: =C8-D8-E8 | G8: =IF(C8=0,0,E8/C8) | Q8: =IF(P8="","-",COUNTIFS('JIRA DATA'!F:F,A8,'JIRA DATA'!J:J,P8,'JIRA DATA'!E:E,"Ready")) | R8: =IF(P8="","-",COUNTIFS('JIRA DATA'!F:F,A8,'JIRA DATA'!J:J,P8)) | S8: =IF(P8="","-",Q8&"/"&R8)
A9: INFRA | B9: INFRA | C9: =COUNTIF('JIRA DATA'!F:F,A9) | D9: =COUNTIFS('JIRA DATA'!F:F,A9,'JIRA DATA'!E:E,"Open") | E9: =COUNTIFS('JIRA DATA'!F:F,A9,'JIRA DATA'!E:E,"Ready") | F9: =C9-D9-E9 | G9: =IF(C9=0,0,E9/C9) | R9: =IF(Q9="","-",COUNTIFS('JIRA DATA'!F:F,A9,'JIRA DATA'!J:J,Q9,'JIRA DATA'!E:E,"Ready")) | S9: =IF(Q9="","-",COUNTIFS('JIRA DATA'!F:F,A9,'JIRA DATA'!J:J,Q9)) | T9: =IF(Q9="","-",R9&"/"&S9)
A10: Language Management | B10: Language Management | C10: =COUNTIF('JIRA DATA'!F:F,A10) | D10: =COUNTIFS('JIRA DATA'!F:F,A10,'JIRA DATA'!E:E,"Open") | E10: =COUNTIFS('JIRA DATA'!F:F,A10,'JIRA DATA'!E:E,"Ready") | F10: =C10-D10-E10 | G10: =IF(C10=0,0,E10/C10) | S10: =IF(R10="","-",COUNTIFS('JIRA DATA'!F:F,A10,'JIRA DATA'!J:J,R10,'JIRA DATA'!E:E,"Ready")) | T10: =IF(R10="","-",COUNTIFS('JIRA DATA'!F:F,A10,'JIRA DATA'!J:J,R10)) | U10: =IF(R10="","-",S10&"/"&T10)
A11: Login | B11: Login | C11: =COUNTIF('JIRA DATA'!F:F,A11) | D11: =COUNTIFS('JIRA DATA'!F:F,A11,'JIRA DATA'!E:E,"Open") | E11: =COUNTIFS('JIRA DATA'!F:F,A11,'JIRA DATA'!E:E,"Ready") | F11: =C11-D11-E11 | G11: =IF(C11=0,0,E11/C11) | T11: =IF(S11="","-",COUNTIFS('JIRA DATA'!F:F,A11,'JIRA DATA'!J:J,S11,'JIRA DATA'!E:E,"Ready")) | U11: =IF(S11="","-",COUNTIFS('JIRA DATA'!F:F,A11,'JIRA DATA'!J:J,S11)) | V11: =IF(S11="","-",T11&"/"&U11)
A12: Logs | B12: Logs | C12: =COUNTIF('JIRA DATA'!F:F,A12) | D12: =COUNTIFS('JIRA DATA'!F:F,A12,'JIRA DATA'!E:E,"Open") | E12: =COUNTIFS('JIRA DATA'!F:F,A12,'JIRA DATA'!E:E,"Ready") | F12: =C12-D12-E12 | G12: =IF(C12=0,0,E12/C12) | U12: =IF(T12="","-",COUNTIFS('JIRA DATA'!F:F,A12,'JIRA DATA'!J:J,T12,'JIRA DATA'!E:E,"Ready")) | V12: =IF(T12="","-",COUNTIFS('JIRA DATA'!F:F,A12,'JIRA DATA'!J:J,T12)) | W12: =IF(T12="","-",U12&"/"&V12)
A13: Map Integrations | B13: Map Integrations | C13: =COUNTIF('JIRA DATA'!F:F,A13) | D13: =COUNTIFS('JIRA DATA'!F:F,A13,'JIRA DATA'!E:E,"Open") | E13: =COUNTIFS('JIRA DATA'!F:F,A13,'JIRA DATA'!E:E,"Ready") | F13: =C13-D13-E13 | G13: =IF(C13=0,0,E13/C13) | V13: =IF(U13="","-",COUNTIFS('JIRA DATA'!F:F,A13,'JIRA DATA'!J:J,U13,'JIRA DATA'!E:E,"Ready")) | W13: =IF(U13="","-",COUNTIFS('JIRA DATA'!F:F,A13,'JIRA DATA'!J:J,U13)) | X13: =IF(U13="","-",V13&"/"&W13)
A14: TECH REQUIREMENTS | B14: TECH REQUIREMENTS | C14: =COUNTIF('JIRA DATA'!F:F,A14) | D14: =COUNTIFS('JIRA DATA'!F:F,A14,'JIRA DATA'!E:E,"Open") | E14: =COUNTIFS('JIRA DATA'!F:F,A14,'JIRA DATA'!E:E,"Ready") | F14: =C14-D14-E14 | G14: =IF(C14=0,0,E14/C14) | W14: =IF(V14="","-",COUNTIFS('JIRA DATA'!F:F,A14,'JIRA DATA'!J:J,V14,'JIRA DATA'!E:E,"Ready")) | X14: =IF(V14="","-",COUNTIFS('JIRA DATA'!F:F,A14,'JIRA DATA'!J:J,V14)) | Y14: =IF(V14="","-",W14&"/"&X14)
A15: Vessel Tracking | B15: Vessel Tracking | C15: =COUNTIF('JIRA DATA'!F:F,A15) | D15: =COUNTIFS('JIRA DATA'!F:F,A15,'JIRA DATA'!E:E,"Open") | E15: =COUNTIFS('JIRA DATA'!F:F,A15,'JIRA DATA'!E:E,"Ready") | F15: =C15-D15-E15 | G15: =IF(C15=0,0,E15/C15) | X15: =IF(W15="","-",COUNTIFS('JIRA DATA'!F:F,A15,'JIRA DATA'!J:J,W15,'JIRA DATA'!E:E,"Ready")) | Y15: =IF(W15="","-",COUNTIFS('JIRA DATA'!F:F,A15,'JIRA DATA'!J:J,W15)) | Z15: =IF(W15="","-",X15&"/"&Y15)

Sheet BURNUP CHART DATA
A1: BURNUP CHART DATA
A2: Session # | B2: Sprint | C2: Stories Refined (Target) | D2: Stories Refined (Actual) | E2: Total Scope | F2: Gap
A3: 0 | B3: 1 | C3: 0 | D3: 0 | E3: =DASHBOARD!$C$7 | F3: 0
A4: {=INDEX('SESSION LOG'!A:A,3)} | B4: {=INDEX('SESSION LOG'!B:B,3)} | C4: =(DASHBOARD!$C$7/15)*(1) | D4: {=INDEX('SESSION LOG'!G:G,3)} | E4: =DASHBOARD!$C$7 | F4: =D4-C4
A5: {=INDEX('SESSION LOG'!A:A,4)} | B5: {=INDEX('SESSION LOG'!B:B,4)} | C5: =(DASHBOARD!$C$7/15)*(2) | D5: {=INDEX('SESSION LOG'!G:G,4)} | E5: =DASHBOARD!$C$7 | F5: =D5-C5
A6: {=INDEX('SESSION LOG'!A:A,5)} | B6: {=INDEX('SESSION LOG'!B:B,5)} | C6: =(DASHBOARD!$C$7/15)*(3) | D6: {=INDEX('SESSION LOG'!G:G,5)} | E6: =DASHBOARD!$C$7 | F6: =D6-C6
A7: {=INDEX('SESSION LOG'!A:A,6)} | B7: {=INDEX('SESSION LOG'!B:B,6)} | C7: =(DASHBOARD!$C$7/15)*(4) | D7: {=INDEX('SESSION LOG'!G:G,6)} | E7: =DASHBOARD!$C$7 | F7: =D7-C7
A8: {=INDEX('SESSION LOG'!A:A,7)} | B8: {=INDEX('SESSION LOG'!B:B,7)} | C8: =(DASHBOARD!$C$7/15)*(5) | D8: {=INDEX('SESSION LOG'!G:G,7)} | E8: =DASHBOARD!$C$7 | F8: =D8-C8
A9: {=INDEX('SESSION LOG'!A:A,8)} | B9: {=INDEX('SESSION LOG'!B:B,8)} | C9: =(DASHBOARD!$C$7/15)*(6) | D9: {=INDEX('SESSION LOG'!G:G,8)} | E9: =DASHBOARD!$C$7 | F9: =D9-C9
A10: {=INDEX('SESSION LOG'!A:A,9)} | B10: {=INDEX('SESSION LOG'!B:B,9)} | C10: =(DASHBOARD!$C$7/15)*(7) | D10: {=INDEX('SESSION LOG'!G:G,9)} | E10: =DASHBOARD!$C$7 | F10: =D10-C10
A11: {=INDEX('SESSION LOG'!A:A,10)} | B11: {=INDEX('SESSION LOG'!B:B,10)} | C11: =(DASHBOARD!$C$7/15)*(8) | D11: {=INDEX('SESSION LOG'!G:G,10)} | E11: =DASHBOARD!$C$7 | F11: =D11-C11
A12: {=INDEX('SESSION LOG'!A:A,11)} | B12: {=INDEX('SESSION LOG'!B:B,11)} | C12: =(DASHBOARD!$C$7/15)*(9) | D12: {=INDEX('SESSION LOG'!G:G,11)} | E12: =DASHBOARD!$C$7 | F12: =D12-C12
A13: {=INDEX('SESSION LOG'!A:A,12)} | B13: {=INDEX('SESSION LOG'!B:B,12)} | C13: =(DASHBOARD!$C$7/15)*(10) | D13: {=INDEX('SESSION LOG'!G:G,12)} | E13: =DASHBOARD!$C$7 | F13: =D13-C13
A14: {=INDEX('SESSION LOG'!A:A,13)} | B14: {=INDEX('SESSION LOG'!B:B,13)} | C14: =(DASHBOARD!$C$7/15)*(11) | D14: {=INDEX('SESSION LOG'!G:G,13)} | E14: =DASHBOARD!$C$7 | F14: =D14-C14
A15: {=INDEX('SESSION LOG'!A:A,14)} | B15: {=INDEX('SESSION LOG'!B:B,14)} | C15: =(DASHBOARD!$C$7/15)*(12) | D15: {=INDEX('SESSION LOG'!G:G,14)} | E15: =DASHBOARD!$C$7 | F15: =D15-C15
A16: {=INDEX('SESSION LOG'!A:A,15)} | B16: {=INDEX('SESSION LOG'!B:B,15)} | C16: =(DASHBOARD!$C$7/15)*(13) | D16: {=INDEX('SESSION LOG'!G:G,15)} | E16: =DASHBOARD!$C$7 | F16: =D16-C16
A17: {=INDEX('SESSION LOG'!A:A,16)} | B17: {=INDEX('SESSION LOG'!B:B,16)} | C17: =(DASHBOARD!$C$7/15)*(14) | D17: {=INDEX('SESSION LOG'!G:G,16)} | E17: =DASHBOARD!$C$7 | F17: =D17-C17
A18: {=INDEX('SESSION LOG'!A:A,17)} | B18: {=INDEX('SESSION LOG'!B:B,17)} | C18: =(DASHBOARD!$C$7/15)*(15) | D18: {=INDEX('SESSION LOG'!G:G,17)} | E18: =DASHBOARD!$C$7 | F18: =D18-C18

Sheet SSF_PI#01 SESSION LOG
A1: SSF_PI#01 REFINEMENT SESSION LOG
A2: Session # | B2: Sprint | C2: Date | D2: PI(s) Worked | E2: Target Stories | F2: Stories Refined | G2: Cumulative | H2: Remaining | I2: Velocity
A3: 1 | B3: ='SESSION LOG'!B3 | C3: ='SESSION LOG'!C3 | D3: ='SESSION LOG'!K3 | E3: ='SESSION LOG'!E3 | F3: =IF(ISNUMBER(SEARCH("SSF_PI#01",'SESSION LOG'!K3)),'SESSION LOG'!F3,0) | G3: =SUM($F$3:F3) | H3: ==COUNTIF('JIRA DATA'!J:J,"SSF_PI#01")-G3 | I3: =F3
A4: 2 | B4: ='SESSION LOG'!B4 | C4: ='SESSION LOG'!C4 | D4: ='SESSION LOG'!K4 | E4: ='SESSION LOG'!E4 | F4: =IF(ISNUMBER(SEARCH("SSF_PI#01",'SESSION LOG'!K4)),'SESSION LOG'!F4,0) | G4: =SUM($F$3:F4) | H4: ==COUNTIF('JIRA DATA'!J:J,"SSF_PI#01")-G4 | I4: =AVERAGE($F$3:F4)
A5: 3 | B5: ='SESSION LOG'!B5 | C5: ='SESSION LOG'!C5 | D5: ='SESSION LOG'!K5 | E5: ='SESSION LOG'!E5 | F5: =IF(ISNUMBER(SEARCH("SSF_PI#01",'SESSION LOG'!K5)),'SESSION LOG'!F5,0) | G5: =SUM($F$3:F5) | H5: ==COUNTIF('JIRA DATA'!J:J,"SSF_PI#01")-G5 | I5: =AVERAGE($F$3:F5)
A6: 4 | B6: ='SESSION LOG'!B6 | C6: ='SESSION LOG'!C6 | D6: ='SESSION LOG'!K6 | E6: ='SESSION LOG'!E6 | F6: =IF(ISNUMBER(SEARCH("SSF_PI#01",'SESSION LOG'!K6)),'SESSION LOG'!F6,0) | G6: =SUM($F$3:F6) | H6: ==COUNTIF('JIRA DATA'!J:J,"SSF_PI#01")-G6 | I6: =AVERAGE($F$3:F6)
A7: 5 | B7: ='SESSION LOG'!B7 | C7: ='SESSION LOG'!C7 | D7: ='SESSION LOG'!K7 | E7: ='SESSION LOG'!E7 | F7: =IF(ISNUMBER(SEARCH("SSF_PI#01",'SESSION LOG'!K7)),'SESSION LOG'!F7,0) | G7: =SUM($F$3:F7) | H7: ==COUNTIF('JIRA DATA'!J:J,"SSF_PI#01")-G7 | I7: =AVERAGE($F$3:F7)
A8: 6 | B8: ='SESSION LOG'!B8 | C8: ='SESSION LOG'!C8 | D8: ='SESSION LOG'!K8 | E8: ='SESSION LOG'!E8 | F8: =IF(ISNUMBER(SEARCH("SSF_PI#01",'SESSION LOG'!K8)),'SESSION LOG'!F8,0) | G8: =SUM($F$3:F8) | H8: ==COUNTIF('JIRA DATA'!J:J,"SSF_PI#01")-G8 | I8: =AVERAGE($F$3:F8)
A9: 7 | B9: ='SESSION LOG'!B9 | C9: ='SESSION LOG'!C9 | D9: ='SESSION LOG'!K9 | E9: ='SESSION LOG'!E9 | F9: =IF(ISNUMBER(SEARCH("SSF_PI#01",'SESSION LOG'!K9)),'SESSION LOG'!F9,0) | G9: =SUM($F$3:F9) | H9: ==COUNTIF('JIRA DATA'!J:J,"SSF_PI#01")-G9 | I9: =AVERAGE($F$3:F9)
A10: 8 | B10: ='SESSION LOG'!B10 | C10: ='SESSION LOG'!C10 | D10: ='SESSION LOG'!K10 | E10: ='SESSION LOG'!E10 | F10: =IF(ISNUMBER(SEARCH("SSF_PI#01",'SESSION LOG'!K10)),'SESSION LOG'!F10,0) | G10: =SUM($F$3:F10) | H10: ==COUNTIF('JIRA DATA'!J:J,"SSF_PI#01")-G10 | I10: =AVERAGE($F$3:F10)
A11: 9 | B11: ='SESSION LOG'!B11 | C11: ='SESSION LOG'!C11 | D11: ='SESSION LOG'!K11 | E11: ='SESSION LOG'!E11 | F11: =IF(ISNUMBER(SEARCH("SSF_PI#01",'SESSION LOG'!K11)),'SESSION LOG'!F11,0) | G11: =SUM($F$3:F11) | H11: ==COUNTIF('JIRA DATA'!J:J,"SSF_PI#01")-G11 | I11: =AVERAGE($F$3:F11)
A12: 10 | B12: ='SESSION LOG'!B12 | C12: ='SESSION LOG'!C12 | D12: ='SESSION LOG'!K12 | E12: ='SESSION LOG'!E12 | F12: =IF(ISNUMBER(SEARCH("SSF_PI#01",'SESSION LOG'!K12)),'SESSION LOG'!F12,0) | G12: =SUM($F$3:F12) | H12: ==COUNTIF('JIRA DATA'!J:J,"SSF_PI#01")-G12 | I12: =AVERAGE($F$3:F12)
A13: 11 | B13: ='SESSION LOG'!B13 | C13: ='SESSION LOG'!C13 | D13: ='SESSION LOG'!K13 | E13: ='SESSION LOG'!E13 | F13: =IF(ISNUMBER(SEARCH("SSF_PI#01",'SESSION LOG'!K13)),'SESSION LOG'!F13,0) | G13: =SUM($F$3:F13) | H13: ==COUNTIF('JIRA DATA'!J:J,"SSF_PI#01")-G13 | I13: =AVERAGE($F$3:F13)
A14: 12 | B14: ='SESSION LOG'!B14 | C14: ='SESSION LOG'!C14 | D14: ='SESSION LOG'!K14 | E14: ='SESSION LOG'!E14 | F14: =IF(ISNUMBER(SEARCH("SSF_PI#01",'SESSION LOG'!K14)),'SESSION LOG'!F14,0) | G14: =SUM($F$3:F14) | H14: ==COUNTIF('JIRA DATA'!J:J,"SSF_PI#01")-G14 | I14: =AVERAGE($F$3:F14)
A15: 13 | B15: ='SESSION LOG'!B15 | C15: ='SESSION LOG'!C15 | D15: ='SESSION LOG'!K15 | E15: ='SESSION LOG'!E15 | F15: =IF(ISNUMBER(SEARCH("SSF_PI#01",'SESSION LOG'!K15)),'SESSION LOG'!F15,0) | G15: =SUM($F$3:F15) | H15: ==COUNTIF('JIRA DATA'!J:J,"SSF_PI#01")-G15 | I15: =AVERAGE($F$3:F15)
... A19: 17 | B19: ='SESSION LOG'!B19 | C19: ='SESSION LOG'!C19 | D19: ='SESSION LOG'!K19 | E19: ='SESSION LOG'!E19 | F19: =IF(ISNUMBER(SEARCH("SSF_PI#01",'SESSION LOG'!K19)),'SESSION LOG'!F19,0) | G19: =SUM($F$3:F19) | H19: ==COUNTIF('JIRA DATA'!J:J,"SSF_PI#01")-G19 | I19: =AVERAGE($F$3:F19)

Sheet SSF_PI#01 BURNDOWN
A1: TARGET SESSIONS: | B1: 15 | D1: SSF_PI#01 BURNDOWN DATA
A2: TOTAL STORIES: | B2: =COUNTIF('JIRA DATA'!J:J,"SSF_PI#01")
A4: Session # | B4: Sprint | C4: IDEAL Remaining | D4: ACTUAL Remaining | E4: Variance | G4: TO CREATE CHART:
A5: 0 | B5: ='SSF_PI#01 SESSION LOG'!B3 | C5: =$B$2-($B$2/$B$1)*A5 | D5: ='SSF_PI#01 SESSION LOG'!H3 | E5: =D5-C5 | G5: 1. Select cells C4:D21
A6: 1 | B6: ='SSF_PI#01 SESSION LOG'!B4 | C6: =$B$2-($B$2/$B$1)*A6 | D6: ='SSF_PI#01 SESSION LOG'!H4 | E6: =D6-C6 | G6: 2. Insert > Chart > Line
A7: 2 | B7: ='SSF_PI#01 SESSION LOG'!B5 | C7: =$B$2-($B$2/$B$1)*A7 | D7: ='SSF_PI#01 SESSION LOG'!H5 | E7: =D7-C7 | G7: 3. Title: See cell D1
A8: 3 | B8: ='SSF_PI#01 SESSION LOG'!B6 | C8: =$B$2-($B$2/$B$1)*A8 | D8: ='SSF_PI#01 SESSION LOG'!H6 | E8: =D8-C8
A9: 4 | B9: ='SSF_PI#01 SESSION LOG'!B7 | C9: =$B$2-($B$2/$B$1)*A9 | D9: ='SSF_PI#01 SESSION LOG'!H7 | E9: =D9-C9
A10: 5 | B10: ='SSF_PI#01 SESSION LOG'!B8 | C10: =$B$2-($B$2/$B$1)*A10 | D10: ='SSF_PI#01 SESSION LOG'!H8 | E10: =D10-C10
A11: 6 | B11: ='SSF_PI#01 SESSION LOG'!B9 | C11: =$B$2-($B$2/$B$1)*A11 | D11: ='SSF_PI#01 SESSION LOG'!H9 | E11: =D11-C11
A12: 7 | B12: ='SSF_PI#01 SESSION LOG'!B10 | C12: =$B$2-($B$2/$B$1)*A12 | D12: ='SSF_PI#01 SESSION LOG'!H10 | E12: =D12-C12
A13: 8 | B13: ='SSF_PI#01 SESSION LOG'!B11 | C13: =$B$2-($B$2/$B$1)*A13 | D13: ='SSF_PI#01 SESSION LOG'!H11 | E13: =D13-C13
A14: 9 | B14: ='SSF_PI#01 SESSION LOG'!B12 | C14: =$B$2-($B$2/$B$1)*A14 | D14: ='SSF_PI#01 SESSION LOG'!H12 | E14: =D14-C14
A15: 10 | B15: ='SSF_PI#01 SESSION LOG'!B13 | C15: =$B$2-($B$2/$B$1)*A15 | D15: ='SSF_PI#01 SESSION LOG'!H13 | E15: =D15-C15
A16: 11 | B16: ='SSF_PI#01 SESSION LOG'!B14 | C16: =$B$2-($B$2/$B$1)*A16 | D16: ='SSF_PI#01 SESSION LOG'!H14 | E16: =D16-C16
A17: 12 | B17: ='SSF_PI#01 SESSION LOG'!B15 | C17: =$B$2-($B$2/$B$1)*A17 | D17: ='SSF_PI#01 SESSION LOG'!H15 | E17: =D17-C17
A18: 13 | B18: ='SSF_PI#01 SESSION LOG'!B16 | C18: =$B$2-($B$2/$B$1)*A18 | D18: ='SSF_PI#01 SESSION LOG'!H16 | E18: =D18-C18
A19: 14 | B19: ='SSF_PI#01 SESSION LOG'!B17 | C19: =$B$2-($B$2/$B$1)*A19 | D19: ='SSF_PI#01 SESSION LOG'!H17 | E19: =D19-C19
... A21: 16 | B21: ='SSF_PI#01 SESSION LOG'!B19 | C21: =$B$2-($B$2/$B$1)*A21 | D21: ='SSF_PI#01 SESSION LOG'!H19 | E21: =D21-C21

Sheet SSF_PI#02 SESSION LOG
A1: SSF_PI#02 REFINEMENT SESSION LOG
A2: Session # | B2: Sprint | C2: Date | D2: PI(s) Worked | E2: Target Stories | F2: Stories Refined | G2: Cumulative | H2: Remaining | I2: Velocity
A3: 1 | B3: ='SESSION LOG'!B3 | C3: ='SESSION LOG'!C3 | D3: ='SESSION LOG'!K3 | E3: ='SESSION LOG'!E3 | F3: =IF(ISNUMBER(SEARCH("SSF_PI#02",'SESSION LOG'!K3)),'SESSION LOG'!F3,0) | G3: =SUM($F$3:F3) | H3: ==COUNTIF('JIRA DATA'!J:J,"SSF_PI#02")-G3 | I3: =F3
A4: 2 | B4: ='SESSION LOG'!B4 | C4: ='SESSION LOG'!C4 | D4: ='SESSION LOG'!K4 | E4: ='SESSION LOG'!E4 | F4: =IF(ISNUMBER(SEARCH("SSF_PI#02",'SESSION LOG'!K4)),'SESSION LOG'!F4,0) | G4: =SUM($F$3:F4) | H4: ==COUNTIF('JIRA DATA'!J:J,"SSF_PI#02")-G4 | I4: =AVERAGE($F$3:F4)
A5: 3 | B5: ='SESSION LOG'!B5 | C5: ='SESSION LOG'!C5 | D5: ='SESSION LOG'!K5 | E5: ='SESSION LOG'!E5 | F5: =IF(ISNUMBER(SEARCH("SSF_PI#02",'SESSION LOG'!K5)),'SESSION LOG'!F5,0) | G5: =SUM($F$3:F5) | H5: ==COUNTIF('JIRA DATA'!J:J,"SSF_PI#02")-G5 | I5: =AVERAGE($F$3:F5)
A6: 4 | B6: ='SESSION LOG'!B6 | C6: ='SESSION LOG'!C6 | D6: ='SESSION LOG'!K6 | E6: ='SESSION LOG'!E6 | F6: =IF(ISNUMBER(SEARCH("SSF_PI#02",'SESSION LOG'!K6)),'SESSION LOG'!F6,0) | G6: =SUM($F$3:F6) | H6: ==COUNTIF('JIRA DATA'!J:J,"SSF_PI#02")-G6 | I6: =AVERAGE($F$3:F6)
A7: 5 | B7: ='SESSION LOG'!B7 | C7: ='SESSION LOG'!C7 | D7: ='SESSION LOG'!K7 | E7: ='SESSION LOG'!E7 | F7: =IF(ISNUMBER(SEARCH("SSF_PI#02",'SESSION LOG'!K7)),'SESSION LOG'!F7,0) | G7: =SUM($F$3:F7) | H7: ==COUNTIF('JIRA DATA'!J:J,"SSF_PI#02")-G7 | I7: =AVERAGE($F$3:F7)
A8: 6 | B8: ='SESSION LOG'!B8 | C8: ='SESSION LOG'!C8 | D8: ='SESSION LOG'!K8 | E8: ='SESSION LOG'!E8 | F8: =IF(ISNUMBER(SEARCH("SSF_PI#02",'SESSION LOG'!K8)),'SESSION LOG'!F8,0) | G8: =SUM($F$3:F8) | H8: ==COUNTIF('JIRA DATA'!J:J,"SSF_PI#02")-G8 | I8: =AVERAGE($F$3:F8)
A9: 7 | B9: ='SESSION LOG'!B9 | C9: ='SESSION LOG'!C9 | D9: ='SESSION LOG'!K9 | E9: ='SESSION LOG'!E9 | F9: =IF(ISNUMBER(SEARCH("SSF_PI#02",'SESSION LOG'!K9)),'SESSION LOG'!F9,0) | G9: =SUM($F$3:F9) | H9: ==COUNTIF('JIRA DATA'!J:J,"SSF_PI#02")-G9 | I9: =AVERAGE($F$3:F9)
A10: 8 | B10: ='SESSION LOG'!B10 | C10: ='SESSION LOG'!C10 | D10: ='SESSION LOG'!K10 | E10: ='SESSION LOG'!E10 | F10: =IF(ISNUMBER(SEARCH("SSF_PI#02",'SESSION LOG'!K10)),'SESSION LOG'!F10,0) | G10: =SUM($F$3:F10) | H10: ==COUNTIF('JIRA DATA'!J:J,"SSF_PI#02")-G10 | I10: =AVERAGE($F$3:F10)
A11: 9 | B11: ='SESSION LOG'!B11 | C11: ='SESSION LOG'!C11 | D11: ='SESSION LOG'!K11 | E11: ='SESSION LOG'!E11 | F11: =IF(ISNUMBER(SEARCH("SSF_PI#02",'SESSION LOG'!K11)),'SESSION LOG'!F11,0) | G11: =SUM($F$3:F11) | H11: ==COUNTIF('JIRA DATA'!J:J,"SSF_PI#02")-G11 | I11: =AVERAGE($F$3:F11)
A12: 10 | B12: ='SESSION LOG'!B12 | C12: ='SESSION LOG'!C12 | D12: ='SESSION LOG'!K12 | E12: ='SESSION LOG'!E12 | F12: =IF(ISNUMBER(SEARCH("SSF_PI#02",'SESSION LOG'!K12)),'SESSION LOG'!F12,0) | G12: =SUM($F$3:F12) | H12: ==COUNTIF('JIRA DATA'!J:J,"SSF_PI#02")-G12 | I12: =AVERAGE($F$3:F12)
A13: 11 | B13: ='SESSION LOG'!B13 | C13: ='SESSION LOG'!C13 | D13: ='SESSION LOG'!K13 | E13: ='SESSION LOG'!E13 | F13: =IF(ISNUMBER(SEARCH("SSF_PI#02",'SESSION LOG'!K13)),'SESSION LOG'!F13,0) | G13: =SUM($F$3:F13) | H13: ==COUNTIF('JIRA DATA'!J:J,"SSF_PI#02")-G13 | I13: =AVERAGE($F$3:F13)
A14: 12 | B14: ='SESSION LOG'!B14 | C14: ='SESSION LOG'!C14 | D14: ='SESSION LOG'!K14 | E14: ='SESSION LOG'!E14 | F14: =IF(ISNUMBER(SEARCH("SSF_PI#02",'SESSION LOG'!K14)),'SESSION LOG'!F14,0) | G14: =SUM($F$3:F14) | H14: ==COUNTIF('JIRA DATA'!J:J,"SSF_PI#02")-G14 | I14: =AVERAGE($F$3:F14)
A15: 13 | B15: ='SESSION LOG'!B15 | C15: ='SESSION LOG'!C15 | D15: ='SESSION LOG'!K15 | E15: ='SESSION LOG'!E15 | F15: =IF(ISNUMBER(SEARCH("SSF_PI#02",'SESSION LOG'!K15)),'SESSION LOG'!F15,0) | G15: =SUM($F$3:F15) | H15: ==COUNTIF('JIRA DATA'!J:J,"SSF_PI#02")-G15 | I15: =AVERAGE($F$3:F15)
... A19: 17 | B19: ='SESSION LOG'!B19 | C19: ='SESSION LOG'!C19 | D19: ='SESSION LOG'!K19 | E19: ='SESSION LOG'!E19 | F19: =IF(ISNUMBER(SEARCH("SSF_PI#02",'SESSION LOG'!K19)),'SESSION LOG'!F19,0) | G19: =SUM($F$3:F19) | H19: ==COUNTIF('JIRA DATA'!J:J,"SSF_PI#02")-G19 | I19: =AVERAGE($F$3:F19)

Sheet SSF_PI#02 BURNDOWN
A1: TARGET SESSIONS: | B1: 15 | D1: SSF_PI#02 BURNDOWN DATA
A2: TOTAL STORIES: | B2: =COUNTIF('JIRA DATA'!J:J,"SSF_PI#02")
A4: Session # | B4: Sprint | C4: IDEAL Remaining | D4: ACTUAL Remaining | E4: Variance | G4: TO CREATE CHART:
A5: 0 | B5: ='SSF_PI#02 SESSION LOG'!B3 | C5: =$B$2-($B$2/$B$1)*A5 | D5: ='SSF_PI#02 SESSION LOG'!H3 | E5: =D5-C5 | G5: 1. Select cells C4:D21
A6: 1 | B6: ='SSF_PI#02 SESSION LOG'!B4 | C6: =$B$2-($B$2/$B$1)*A6 | D6: ='SSF_PI#02 SESSION LOG'!H4 | E6: =D6-C6 | G6: 2. Insert > Chart > Line
A7: 2 | B7: ='SSF_PI#02 SESSION LOG'!B5 | C7: =$B$2-($B$2/$B$1)*A7 | D7: ='SSF_PI#02 SESSION LOG'!H5 | E7: =D7-C7 | G7: 3. Title: See cell D1
A8: 3 | B8: ='SSF_PI#02 SESSION LOG'!B6 | C8: =$B$2-($B$2/$B$1)*A8 | D8: ='SSF_PI#02 SESSION LOG'!H6 | E8: =D8-C8
A9: 4 | B9: ='SSF_PI#02 SESSION LOG'!B7 | C9: =$B$2-($B$2/$B$1)*A9 | D9: ='SSF_PI#02 SESSION LOG'!H7 | E9: =D9-C9
A10: 5 | B10: ='SSF_PI#02 SESSION LOG'!B8 | C10: =$B$2-($B$2/$B$1)*A10 | D10: ='SSF_PI#02 SESSION LOG'!H8 | E10: =D10-C10
A11: 6 | B11: ='SSF_PI#02 SESSION LOG'!B9 | C11: =$B$2-($B$2/$B$1)*A11 | D11: ='SSF_PI#02 SESSION LOG'!H9 | E11: =D11-C11
A12: 7 | B12: ='SSF_PI#02 SESSION LOG'!B10 | C12: =$B$2-($B$2/$B$1)*A12 | D12: ='SSF_PI#02 SESSION LOG'!H10 | E12: =D12-C12
A13: 8 | B13: ='SSF_PI#02 SESSION LOG'!B11 | C13: =$B$2-($B$2/$B$1)*A13 | D13: ='SSF_PI#02 SESSION LOG'!H11 | E13: =D13-C13
A14: 9 | B14: ='SSF_PI#02 SESSION LOG'!B12 | C14: =$B$2-($B$2/$B$1)*A14 | D14: ='SSF_PI#02 SESSION LOG'!H12 | E14: =D14-C14
A15: 10 | B15: ='SSF_PI#02 SESSION LOG'!B13 | C15: =$B$2-($B$2/$B$1)*A15 | D15: ='SSF_PI#02 SESSION LOG'!H13 | E15: =D15-C15
A16: 11 | B16: ='SSF_PI#02 SESSION LOG'!B14 | C16: =$B$2-($B$2/$B$1)*A16 | D16: ='SSF_PI#02 SESSION LOG'!H14 | E16: =D16-C16
A17: 12 | B17: ='SSF_PI#02 SESSION LOG'!B15 | C17: =$B$2-($B$2/$B$1)*A17 | D17: ='SSF_PI#02 SESSION LOG'!H15 | E17: =D17-C17
A18: 13 | B18: ='SSF_PI#02 SESSION LOG'!B16 | C18: =$B$2-($B$2/$B$1)*A18 | D18: ='SSF_PI#02 SESSION LOG'!H16 | E18: =D18-C18
A19: 14 | B19: ='SSF_PI#02 SESSION LOG'!B17 | C19: =$B$2-($B$2/$B$1)*A19 | D19: ='SSF_PI#02 SESSION LOG'!H17 | E19: =D19-C19
... A21: 16 | B21: ='SSF_PI#02 SESSION LOG'!B19 | C21: =$B$2-($B$2/$B$1)*A21 | D21: ='SSF_PI#02 SESSION LOG'!H19 | E21: =D21-C21
